{"name": "test_error_without_traceback", "status": "passed", "description": "Verify error() logs at the ERROR level without a traceback.", "start": 1756776131269, "stop": 1756776131271, "uuid": "72e4c058-896d-469a-84bf-2832fd41efef", "historyId": "3046a012cff151115e61e02786daf834", "testCaseId": "3046a012cff151115e61e02786daf834", "fullName": "test.utilities.test_cli.TestAlertFunctions#test_error_without_traceback", "labels": [{"name": "parentSuite", "value": "test.utilities"}, {"name": "suite", "value": "test_cli"}, {"name": "subSuite", "value": "TestAlertFunctions"}, {"name": "host", "value": "dtc205659"}, {"name": "thread", "value": "535219-MainThread"}, {"name": "framework", "value": "pytest"}, {"name": "language", "value": "cpython3"}, {"name": "package", "value": "test.utilities.test_cli"}], "titlePath": ["test", "utilities", "test_cli.py", "TestAlertFunctions"]}
