{"name": "test_error_with_traceback", "status": "passed", "description": "Verify that error() with exc_info=True prints a traceback.", "start": 1756776344546, "stop": 1756776344548, "uuid": "c32ea04d-c5b2-44f8-86c0-0bc1d1299805", "historyId": "e000f07e64de5d1dc176670607565acb", "testCaseId": "e000f07e64de5d1dc176670607565acb", "fullName": "test.utilities.test_cli.TestAlertFunctions#test_error_with_traceback", "labels": [{"name": "parentSuite", "value": "test.utilities"}, {"name": "suite", "value": "test_cli"}, {"name": "subSuite", "value": "TestAlertFunctions"}, {"name": "host", "value": "dtc205659"}, {"name": "thread", "value": "538732-MainThread"}, {"name": "framework", "value": "pytest"}, {"name": "language", "value": "cpython3"}, {"name": "package", "value": "test.utilities.test_cli"}], "titlePath": ["test", "utilities", "test_cli.py", "TestAlertFunctions"]}
