{"name": "test_error_with_traceback", "status": "passed", "description": "Verify that error() with exc_info=True prints a traceback.", "start": 1756776652922, "stop": 1756776652926, "uuid": "fd1f949a-cebf-4378-b5a6-44a10d909eb7", "historyId": "e000f07e64de5d1dc176670607565acb", "testCaseId": "e000f07e64de5d1dc176670607565acb", "fullName": "test.utilities.test_cli.TestAlertFunctions#test_error_with_traceback", "labels": [{"name": "parentSuite", "value": "test.utilities"}, {"name": "suite", "value": "test_cli"}, {"name": "subSuite", "value": "TestAlertFunctions"}, {"name": "host", "value": "dtc205659"}, {"name": "thread", "value": "543787-MainThread"}, {"name": "framework", "value": "pytest"}, {"name": "language", "value": "cpython3"}, {"name": "package", "value": "test.utilities.test_cli"}], "titlePath": ["test", "utilities", "test_cli.py", "TestAlertFunctions"]}
