{"name": "test_error_with_traceback", "status": "passed", "description": "Verify that error() with exc_info=True prints a traceback.", "start": 1756775768738, "stop": 1756775768741, "uuid": "a4afecd7-c8d3-4b13-a444-d856e3a5b04e", "historyId": "e000f07e64de5d1dc176670607565acb", "testCaseId": "e000f07e64de5d1dc176670607565acb", "fullName": "test.utilities.test_cli.TestAlertFunctions#test_error_with_traceback", "labels": [{"name": "parentSuite", "value": "test.utilities"}, {"name": "suite", "value": "test_cli"}, {"name": "subSuite", "value": "TestAlertFunctions"}, {"name": "host", "value": "dtc205659"}, {"name": "thread", "value": "529406-MainThread"}, {"name": "framework", "value": "pytest"}, {"name": "language", "value": "cpython3"}, {"name": "package", "value": "test.utilities.test_cli"}], "titlePath": ["test", "utilities", "test_cli.py", "TestAlertFunctions"]}
