{"name": "test_error_with_traceback", "status": "passed", "description": "Verify that error() with exc_info=True prints a traceback.", "start": 1756776466261, "stop": 1756776466263, "uuid": "2db7011c-0fa4-4935-ab4b-d586096a7052", "historyId": "e000f07e64de5d1dc176670607565acb", "testCaseId": "e000f07e64de5d1dc176670607565acb", "fullName": "test.utilities.test_cli.TestAlertFunctions#test_error_with_traceback", "labels": [{"name": "parentSuite", "value": "test.utilities"}, {"name": "suite", "value": "test_cli"}, {"name": "subSuite", "value": "TestAlertFunctions"}, {"name": "host", "value": "dtc205659"}, {"name": "thread", "value": "540663-MainThread"}, {"name": "framework", "value": "pytest"}, {"name": "language", "value": "cpython3"}, {"name": "package", "value": "test.utilities.test_cli"}], "titlePath": ["test", "utilities", "test_cli.py", "TestAlertFunctions"]}
